{
 "cells": [
  {
   "cell_type": "code",
   "execution_count": 3,
   "id": "1acac014-681a-452c-acc3-fe4b0076f4b8",
   "metadata": {},
   "outputs": [],
   "source": [
    "import tensorflow as tf\n",
    "from tensorflow import keras"
   ]
  },
  {
   "cell_type": "code",
   "execution_count": 4,
   "id": "d07d0b76-0196-406a-8785-d6c5b5cd75a4",
   "metadata": {},
   "outputs": [
    {
     "name": "stdout",
     "output_type": "stream",
     "text": [
      "Downloading data from https://storage.googleapis.com/tensorflow/keras-applications/mobilenet_v2/mobilenet_v2_weights_tf_dim_ordering_tf_kernels_1.0_224.h5\n",
      "14540800/14536120 [==============================] - 7s 0us/step\n",
      "14548992/14536120 [==============================] - 7s 0us/step\n"
     ]
    }
   ],
   "source": [
    "model = keras.applications.MobileNetV2(weights='imagenet')"
   ]
  },
  {
   "cell_type": "code",
   "execution_count": 5,
   "id": "f4ef1da4-5050-4c10-a665-94aa40f25f7e",
   "metadata": {},
   "outputs": [
    {
     "name": "stdout",
     "output_type": "stream",
     "text": [
      "Unexpected exception formatting exception. Falling back to standard exception\n"
     ]
    },
    {
     "name": "stderr",
     "output_type": "stream",
     "text": [
      "Traceback (most recent call last):\n",
      "  File \"c:\\python37\\lib\\site-packages\\IPython\\core\\interactiveshell.py\", line 3550, in run_code\n",
      "    exec(code_obj, self.user_global_ns, self.user_ns)\n",
      "  File \"C:\\Users\\Mehtab\\AppData\\Local\\Temp\\ipykernel_24052\\461932448.py\", line 1, in <module>\n",
      "    img = keras.preprocessing.image.load_img('path/to/image.jpg', target_size=(224, 224))\n",
      "  File \"c:\\python37\\lib\\site-packages\\keras\\preprocessing\\image.py\", line 313, in load_img\n",
      "    return image.load_img(path, grayscale=grayscale, color_mode=color_mode,\n",
      "  File \"c:\\python37\\lib\\site-packages\\keras_preprocessing\\image\\utils.py\", line 113, in load_img\n",
      "    with open(path, 'rb') as f:\n",
      "FileNotFoundError: [Errno 2] No such file or directory: 'path/to/image.jpg'\n",
      "\n",
      "During handling of the above exception, another exception occurred:\n",
      "\n",
      "Traceback (most recent call last):\n",
      "  File \"c:\\python37\\lib\\site-packages\\IPython\\core\\interactiveshell.py\", line 2144, in showtraceback\n",
      "    stb = self.InteractiveTB.structured_traceback(\n",
      "  File \"c:\\python37\\lib\\site-packages\\IPython\\core\\ultratb.py\", line 1435, in structured_traceback\n",
      "    return FormattedTB.structured_traceback(\n",
      "  File \"c:\\python37\\lib\\site-packages\\IPython\\core\\ultratb.py\", line 1326, in structured_traceback\n",
      "    return VerboseTB.structured_traceback(\n",
      "  File \"c:\\python37\\lib\\site-packages\\IPython\\core\\ultratb.py\", line 1173, in structured_traceback\n",
      "    formatted_exception = self.format_exception_as_a_whole(etype, evalue, etb, number_of_lines_of_context,\n",
      "  File \"c:\\python37\\lib\\site-packages\\IPython\\core\\ultratb.py\", line 1063, in format_exception_as_a_whole\n",
      "    self.get_records(etb, number_of_lines_of_context, tb_offset) if etb else []\n",
      "  File \"c:\\python37\\lib\\site-packages\\IPython\\core\\ultratb.py\", line 1115, in get_records\n",
      "    style = stack_data.style_with_executing_node(style, self._tb_highlight)\n",
      "  File \"c:\\python37\\lib\\site-packages\\stack_data\\core.py\", line 455, in style_with_executing_node\n",
      "    class NewStyle(style):\n",
      "  File \"c:\\python37\\lib\\site-packages\\pygments\\style.py\", line 91, in __new__\n",
      "    ndef[4] = colorformat(styledef[3:])\n",
      "  File \"c:\\python37\\lib\\site-packages\\pygments\\style.py\", line 58, in colorformat\n",
      "    assert False, \"wrong color format %r\" % text\n",
      "AssertionError: wrong color format 'ansiyellow'\n"
     ]
    }
   ],
   "source": [
    "img = keras.preprocessing.image.load_img('path/to/image.jpg', target_size=(224, 224))\n",
    "img_array = keras.preprocessing.image.img_to_array(img)\n",
    "img_array = tf.expand_dims(img_array, axis=0)\n",
    "img_array = keras.applications.mobilenet_v2.preprocess_input(img_array)"
   ]
  },
  {
   "cell_type": "code",
   "execution_count": 6,
   "id": "eed3851a-436f-48f5-a569-44adebbbe151",
   "metadata": {},
   "outputs": [
    {
     "name": "stdout",
     "output_type": "stream",
     "text": [
      "Unexpected exception formatting exception. Falling back to standard exception\n"
     ]
    },
    {
     "name": "stderr",
     "output_type": "stream",
     "text": [
      "Traceback (most recent call last):\n",
      "  File \"c:\\python37\\lib\\site-packages\\IPython\\core\\interactiveshell.py\", line 3550, in run_code\n",
      "    exec(code_obj, self.user_global_ns, self.user_ns)\n",
      "  File \"C:\\Users\\Mehtab\\AppData\\Local\\Temp\\ipykernel_24052\\2200951855.py\", line 1, in <module>\n",
      "    predictions = model.predict(img_array)\n",
      "NameError: name 'img_array' is not defined\n",
      "\n",
      "During handling of the above exception, another exception occurred:\n",
      "\n",
      "Traceback (most recent call last):\n",
      "  File \"c:\\python37\\lib\\site-packages\\IPython\\core\\interactiveshell.py\", line 2144, in showtraceback\n",
      "    stb = self.InteractiveTB.structured_traceback(\n",
      "  File \"c:\\python37\\lib\\site-packages\\IPython\\core\\ultratb.py\", line 1435, in structured_traceback\n",
      "    return FormattedTB.structured_traceback(\n",
      "  File \"c:\\python37\\lib\\site-packages\\IPython\\core\\ultratb.py\", line 1326, in structured_traceback\n",
      "    return VerboseTB.structured_traceback(\n",
      "  File \"c:\\python37\\lib\\site-packages\\IPython\\core\\ultratb.py\", line 1173, in structured_traceback\n",
      "    formatted_exception = self.format_exception_as_a_whole(etype, evalue, etb, number_of_lines_of_context,\n",
      "  File \"c:\\python37\\lib\\site-packages\\IPython\\core\\ultratb.py\", line 1063, in format_exception_as_a_whole\n",
      "    self.get_records(etb, number_of_lines_of_context, tb_offset) if etb else []\n",
      "  File \"c:\\python37\\lib\\site-packages\\IPython\\core\\ultratb.py\", line 1115, in get_records\n",
      "    style = stack_data.style_with_executing_node(style, self._tb_highlight)\n",
      "  File \"c:\\python37\\lib\\site-packages\\stack_data\\core.py\", line 455, in style_with_executing_node\n",
      "    class NewStyle(style):\n",
      "  File \"c:\\python37\\lib\\site-packages\\pygments\\style.py\", line 91, in __new__\n",
      "    ndef[4] = colorformat(styledef[3:])\n",
      "  File \"c:\\python37\\lib\\site-packages\\pygments\\style.py\", line 58, in colorformat\n",
      "    assert False, \"wrong color format %r\" % text\n",
      "AssertionError: wrong color format 'ansiyellow'\n"
     ]
    }
   ],
   "source": [
    "predictions = model.predict(img_array)\n",
    "decoded_predictions = keras.applications.mobilenet_v2.decode_predictions(predictions, top=5)[0]\n",
    "\n",
    "for i in decoded_predictions:\n",
    "    print(f\"{i[1]}: {i[2]*100:.2f}%\")"
   ]
  },
  {
   "cell_type": "code",
   "execution_count": null,
   "id": "92e33db5-3f29-458b-bdbf-5b621be648a2",
   "metadata": {},
   "outputs": [],
   "source": []
  }
 ],
 "metadata": {
  "kernelspec": {
   "display_name": "Python 3 (ipykernel)",
   "language": "python",
   "name": "python3"
  },
  "language_info": {
   "codemirror_mode": {
    "name": "ipython",
    "version": 3
   },
   "file_extension": ".py",
   "mimetype": "text/x-python",
   "name": "python",
   "nbconvert_exporter": "python",
   "pygments_lexer": "ipython3",
   "version": "3.9.2"
  }
 },
 "nbformat": 4,
 "nbformat_minor": 5
}
